Exception in thread Thread-5:
Traceback (most recent call last):
  File "/home/autoc4/.pyenv/versions/3.4.0/lib/python3.4/threading.py", line 921, in _bootstrap_inner
    self.run()
  File "mpd-transport.py", line 194, in run
    self.got_event()
  File "mpd-transport.py", line 220, in got_event
    self.publish_new_state()
  File "mpd-transport.py", line 225, in publish_new_state
    song_obj.update(self.client.currentsong())
  File "/home/autoc4/.pyenv/versions/3.4.0/lib/python3.4/site-packages/mpd.py", line 583, in decorator
    return wrapper(self, name, args, bound_decorator(self, returnValue))
  File "/home/autoc4/.pyenv/versions/3.4.0/lib/python3.4/site-packages/mpd.py", line 229, in _execute
    return retval()
  File "/home/autoc4/.pyenv/versions/3.4.0/lib/python3.4/site-packages/mpd.py", line 578, in decorator
    return function(self, *args, **kwargs)
  File "/home/autoc4/.pyenv/versions/3.4.0/lib/python3.4/site-packages/mpd.py", line 377, in _fetch_object
    objs = list(self._read_objects())
  File "/home/autoc4/.pyenv/versions/3.4.0/lib/python3.4/site-packages/mpd.py", line 305, in _read_objects
    for key, value in self._read_pairs():
  File "/home/autoc4/.pyenv/versions/3.4.0/lib/python3.4/site-packages/mpd.py", line 284, in _read_pairs
    pair = self._read_pair(separator)
  File "/home/autoc4/.pyenv/versions/3.4.0/lib/python3.4/site-packages/mpd.py", line 275, in _read_pair
    line = self._read_line()
  File "/home/autoc4/.pyenv/versions/3.4.0/lib/python3.4/site-packages/mpd.py", line 255, in _read_line
    line = self._rfile.readline()
  File "/home/autoc4/.pyenv/versions/3.4.0/lib/python3.4/codecs.py", line 313, in decode
    (result, consumed) = self._buffer_decode(data, self.errors, final)
UnicodeDecodeError: 'utf-8' codec can't decode byte 0xed in position 232: invalid continuation byte
